<?xml version="1.0"?>
<robot xmlns:xacro="http://www.ros.org/wiki/xacro" name="mp_400_wheel">
	<xacro:macro name="wheel" params="name parent *joint_origin wheel_length:=0.025 wheel_radius=0.078">
		<link name="${name}_wheel_link">
			<inertial>
				<mass value="2" />
				<origin xyz="0 0 0" />
				<inertia ixx="0.2467" ixy="0" ixz="0"
				         iyy="0.04411" iyz="0" izz="0.02467" />
			</inertial>
			<visual>
				<origin xyz="0 0 0" rpy="0 0 0"/>
				<geometry>
					<mesh filename="package://neo_simulation/robots/mp_400/meshes/MP-400-FIXED-WHEEL-LEFT.dae" scale="0.001 0.001 0.001"/>
				</geometry>
			</visual>
			<collision>
				<origin xyz="0 0 0" rpy="0 ${pi/2} 0" />
				<geometry>
					<cylinder length="${wheel_length}" radius="${wheel_radius}" />
				</geometry>
			</collision>
		</link>

		<gazebo reference="${name}_wheel_link">
			<mu1 value="1.0"/>
			<mu2 value="1.0"/>
			<kp value="1000000.0" />
			<kd value="100.0" />
			<minDepth>0.001</minDepth>
			<fdir value="1 0 0"/>
		</gazebo>

		<joint name="${name}_wheel" type="continuous">
			<parent link="${parent}"/>
			<child link="${name}_wheel_link"/>
			<xacro:insert_block name="joint_origin"/>
			<axis xyz="1 0 0" rpy="0 0 0"/>
			<dynamics damping="50" friction="1"/>
		</joint>

		<transmission name="${name}_wheel_trans" type="SimpleTransmission">
			<type>transmission_interface/SimpleTransmission</type>
			<actuator name="${name}_wheel_motor">
				<mechanicalReduction>1</mechanicalReduction>
			</actuator>
			<joint name="${name}_wheel">
				<hardwareInterface>hardware_interface/VelocityJointInterface</hardwareInterface>
			</joint>
		</transmission>
	</xacro:macro>
</robot>
