<?xml version='1.0' encoding='utf-8'?>
<robot xmlns:xacro="http://www.ros.org/wiki/xacro" name="panda">
	<xacro:macro name="panda_arm" params="arm_id:='panda' description_pkg:='franka_description' connected_to:='' xyz:='0 0 0' rpy:='0 0 0'">
		<xacro:macro name="arm_link" params="prefix id *geometry_mesh *collision_mesh mass:=0.1">
			<link name="${prefix}_link${id}">
				<visual>
					<geometry>
						<xacro:insert_block name="geometry_mesh"/>
					</geometry>
				</visual>
				<collision>
					<geometry>
						<xacro:insert_block name="collision_mesh"/>
					</geometry>
				</collision>
				<inertial>
					<origin xyz="0 0 0" rpy="0 0 0" />
					<mass value="${mass}"/>
					<inertia ixx="0.3" ixy="0.0" ixz="0.0" iyy="0.3" iyz="0.0" izz="0.3" />
				</inertial>
			</link>
		</xacro:macro>

		<xacro:arm_link prefix="${arm_id}" id="0">
			<mesh filename="package://${description_pkg}/meshes/visual/link0.dae"/>
			<mesh filename="package://${description_pkg}/meshes/collision/link0.stl"/>
		</xacro:arm_link>
		<xacro:arm_link prefix="${arm_id}" id="1">
			<mesh filename="package://${description_pkg}/meshes/visual/link1.dae"/>
			<mesh filename="package://${description_pkg}/meshes/collision/link1.stl"/>
		</xacro:arm_link>
		<xacro:arm_link prefix="${arm_id}" id="2">
			<mesh filename="package://${description_pkg}/meshes/visual/link2.dae"/>
			<mesh filename="package://${description_pkg}/meshes/collision/link2.stl"/>
		</xacro:arm_link>
		<xacro:arm_link prefix="${arm_id}" id="3">
			<mesh filename="package://${description_pkg}/meshes/visual/link3.dae"/>
			<mesh filename="package://${description_pkg}/meshes/collision/link3.stl"/>
		</xacro:arm_link>
		<xacro:arm_link prefix="${arm_id}" id="4">
			<mesh filename="package://${description_pkg}/meshes/visual/link4.dae"/>
			<mesh filename="package://${description_pkg}/meshes/collision/link4.stl"/>
		</xacro:arm_link>
		<xacro:arm_link prefix="${arm_id}" id="5">
			<mesh filename="package://${description_pkg}/meshes/visual/link5.dae"/>
			<mesh filename="package://${description_pkg}/meshes/collision/link5.stl"/>
		</xacro:arm_link>
		<xacro:arm_link prefix="${arm_id}" id="6">
			<mesh filename="package://${description_pkg}/meshes/visual/link6.dae"/>
			<mesh filename="package://${description_pkg}/meshes/collision/link6.stl"/>
		</xacro:arm_link>
		<xacro:arm_link prefix="${arm_id}" id="7">
			<mesh filename="package://${description_pkg}/meshes/visual/link7.dae"/>
			<mesh filename="package://${description_pkg}/meshes/collision/link7.stl"/>
		</xacro:arm_link>
		<link name="${arm_id}_link8"/>

		<xacro:if value="${connected_to != ''}">
			<joint name="${arm_id}_joint_${connected_to}" type="fixed">
				<parent link="${connected_to}"/>
				<child link="${arm_id}_link0"/>
				<origin rpy="${rpy}" xyz="${xyz}"/>
			</joint>
		</xacro:if>
		<joint name="${arm_id}_joint1" type="revolute">
			<safety_controller k_position="100.0" k_velocity="40.0" soft_lower_limit="-2.8973" soft_upper_limit="2.8973"/>
			<origin rpy="0 0 0" xyz="0 0 0.333"/>
			<parent link="${arm_id}_link0"/>
			<child link="${arm_id}_link1"/>
			<axis xyz="0 0 1"/>
			<limit effort="87" lower="-2.8973" upper="2.8973" velocity="2.1750"/>
			<dynamics damping="1.0"/>
		</joint>
		<joint name="${arm_id}_joint2" type="revolute">
			<safety_controller k_position="100.0" k_velocity="40.0" soft_lower_limit="-1.7628" soft_upper_limit="1.7628"/>
			<origin rpy="${-pi/2} 0 0" xyz="0 0 0"/>
			<parent link="${arm_id}_link1"/>
			<child link="${arm_id}_link2"/>
			<axis xyz="0 0 1"/>
			<limit effort="87" lower="-1.7628" upper="1.7628" velocity="2.1750"/>
			<dynamics damping="1.0"/>
		</joint>
		<joint name="${arm_id}_joint3" type="revolute">
			<safety_controller k_position="100.0" k_velocity="40.0" soft_lower_limit="-2.8973" soft_upper_limit="2.8973"/>
			<origin rpy="${pi/2} 0 0" xyz="0 -0.316 0"/>
			<parent link="${arm_id}_link2"/>
			<child link="${arm_id}_link3"/>
			<axis xyz="0 0 1"/>
			<limit effort="87" lower="-2.8973" upper="2.8973" velocity="2.1750"/>
			<dynamics damping="1.0"/>
		</joint>
		<joint name="${arm_id}_joint4" type="revolute">
			<safety_controller k_position="100.0" k_velocity="40.0" soft_lower_limit="-3.0718" soft_upper_limit="-0.0698"/>
			<origin rpy="${pi/2} 0 0" xyz="0.0825 0 0"/>
			<parent link="${arm_id}_link3"/>
			<child link="${arm_id}_link4"/>
			<axis xyz="0 0 1"/>
			<limit effort="87" lower="-3.0718" upper="-0.0698" velocity="2.1750"/>
			<dynamics damping="1.0"/>
		</joint>
		<joint name="${arm_id}_joint5" type="revolute">
			<safety_controller k_position="100.0" k_velocity="40.0" soft_lower_limit="-2.8973" soft_upper_limit="2.8973"/>
			<origin rpy="${-pi/2} 0 0" xyz="-0.0825 0.384 0"/>
			<parent link="${arm_id}_link4"/>
			<child link="${arm_id}_link5"/>
			<axis xyz="0 0 1"/>
			<limit effort="12" lower="-2.8973" upper="2.8973" velocity="2.6100"/>
			<dynamics damping="1.0"/>
		</joint>
		<joint name="${arm_id}_joint6" type="revolute">
			<safety_controller k_position="100.0" k_velocity="40.0" soft_lower_limit="-0.0175" soft_upper_limit="3.7525"/>
			<origin rpy="${pi/2} 0 0" xyz="0 0 0"/>
			<parent link="${arm_id}_link5"/>
			<child link="${arm_id}_link6"/>
			<axis xyz="0 0 1"/>
			<limit effort="12" lower="-0.0175" upper="3.7525" velocity="2.6100"/>
			<dynamics damping="1.0"/>
		</joint>
		<joint name="${arm_id}_joint7" type="revolute">
			<safety_controller k_position="100.0" k_velocity="40.0" soft_lower_limit="-2.8973" soft_upper_limit="2.8973"/>
			<origin rpy="${pi/2} 0 0" xyz="0.088 0 0"/>
			<parent link="${arm_id}_link6"/>
			<child link="${arm_id}_link7"/>
			<axis xyz="0 0 1"/>
			<limit effort="12" lower="-2.8973" upper="2.8973" velocity="2.6100"/>
			<dynamics damping="1.0"/>
		</joint>
		<joint name="${arm_id}_joint8" type="fixed">
			<origin rpy="0 0 0" xyz="0 0 0.107"/>
			<parent link="${arm_id}_link7"/>
			<child link="${arm_id}_link8"/>
			<axis xyz="0 0 0"/>
		</joint>
	</xacro:macro>
</robot>
